Workbook

Sheet Cases
A1: Case | B1: Formula | C1: Excel result
A2: Arithmetic precedence | B2: =1+2*3 | C2: =1+2*3 -> 7
A3: Unary minus vs power | B3: =-2^2 | C3: =-2^2 -> 4
A4: Power right associative | B4: =2^3^2 | C4: =2^3^2 -> 64
A5: Division | B5: =10/4 | C5: =10/4 -> 2.5
A6: One third | B6: =1/3 | C6: =1/3 -> 0.33333333
A7: Point one plus point two | B7: =0.1+0.2 | C7: =0.1+0.2 -> 0.3
A8: Overflow | B8: =2^1024 | C8: =2^1024 -> #NUM!
A9: Division by zero | B9: =1/0 | C9: =1/0 -> #DIV/0!
A10: Square root domain | B10: =SQRT(-1) | C10: =SQRT(-1) -> #NUM!
A11: Round trap | B11: =ROUND(2.675,2) | C11: =ROUND(2.675,2) -> 2.68
A12: Round negative trap | B12: =ROUND(-2.675,2) | C12: =ROUND(-2.675,2) -> -2.68
A13: Round hundreds | B13: =ROUND(1234,-2) | C13: =ROUND(1234,-2) -> 1200
A14: Round half away | B14: =ROUND(2.5,0) | C14: =ROUND(2.5,0) -> 3
A15: Mod negative | B15: =MOD(-3,2) | C15: =MOD(-3,2) -> 1
A16: Sum range | B16: =SUM(Inputs!A1:A5) | C16: =SUM(Inputs!A1:A5) -> 30
A17: Average range | B17: =AVERAGE(Inputs!A1:A5) | C17: =AVERAGE(Inputs!A1:A5) -> 15
A18: Count range | B18: =COUNT(Inputs!A1:A5) | C18: =COUNT(Inputs!A1:A5) -> 2
A19: Counta range | B19: =COUNTA(Inputs!A1:A5) | C19: =COUNTA(Inputs!A1:A5) -> 4
A20: Countblank range | B20: =COUNTBLANK(Inputs!A1:A5) | C20: =COUNTBLANK(Inputs!A1:A5) -> 1
A21: Min range | B21: =MIN(Inputs!A1:A5) | C21: =MIN(Inputs!A1:A5) -> 10
A22: Max range | B22: =MAX(Inputs!A1:A5) | C22: =MAX(Inputs!A1:A5) -> 20
A23: Product range | B23: =PRODUCT(Inputs!A1:A5) | C23: =PRODUCT(Inputs!A1:A5) -> 200
A24: Sumproduct | B24: =SUMPRODUCT(Inputs!B1:B3,Inputs!C1:C3) | C24: =SUMPRODUCT(Inputs!B1:B3,Inputs!C1:C3) -> 32
A25: If lazy | B25: =IF(TRUE,1,1/0) | C25: =IF(TRUE,1,1/0) -> 1
A26: Iferror | B26: =IFERROR(1/0,42) | C26: =IFERROR(1/0,42) -> 42
A27: Ifna | B27: =IFNA(NA(),42) | C27: =_xlfn.IFNA(NA(),42) -> 42
A28: And | B28: =AND(TRUE,1,2) | C28: =AND(TRUE,1,2) -> TRUE
A29: Or | B29: =OR(FALSE,0,1) | C29: =OR(FALSE,0,1) -> TRUE
A30: Concat | B30: =CONCAT("a",1,TRUE) | C30: =_xlfn.CONCAT("a",1,TRUE) -> a1TRUE
A31: Left | B31: =LEFT("hello",2) | C31: =LEFT("hello",2) -> he
A32: Right | B32: =RIGHT("hello",2) | C32: =RIGHT("hello",2) -> lo
A33: Mid | B33: =MID("hello",2,3) | C33: =MID("hello",2,3) -> ell
A34: Len text | B34: =LEN("hello") | C34: =LEN("hello") -> 5
A35: Upper | B35: =UPPER("abc") | C35: =UPPER("abc") -> ABC
A36: Trim | B36: =TRIM(" a b ") | C36: =TRIM(" a b ") -> a b
A37: Text compare | B37: ="a"="A" | C37: ="a"="A" -> TRUE
A38: Number vs text | B38: =1="1" | C38: =1="1" -> FALSE
A39: Less than | B39: =1<2 | C39: =1<2 -> TRUE
A40: Exact | B40: =EXACT("a","A") | C40: =EXACT("a","A") -> FALSE
...

Sheet Inputs
A1: 10 | B1: 1 | C1: 4
A2: 20 | B2: 2 | C2: 5
A3: text | B3: 3 | C3: 6
A4: TRUE
